Workbook

Sheet Transactions
A1: Transaction ID | B1: Transaction Date | C1: Customer Name | D1: Region | E1: City | F1: Account Manager | G1: Product | H1: Product Type | I1: Quantity | J1: Unit Price (INR) | K1: Discount % | L1: Tax Included | M1: Currency | N1: Billing Cycle | O1: Payment Method | P1: Status | Q1: Renewal Date | R1: Net Amount | S1: Tax Amount (18% GST) | T1: Final Amount | U1: Quarter
A2: TXN-1000 | B2: 45753 | C2: SwiftLogic Labs | D2: North | E2: Jaipur | F2: SNEHA IYER | G2: Enterprise Plan | H2: Subscription | I2: 1 | J2: 9999 | K2: 0 | L2: Yes | M2: INR | N2: Monthly | O2: Cheque | P2: Active | Q2: 45783 | R2: =IF(P2="Active", I2*J2*(1-K2/100), 0) -> 9999 | S2: =IF(L2="Yes", R2-(R2/1.18), R2*0.18) -> 1525.2712 | T2: =IF(L2="Yes", R2, R2+S2) -> 9999 | U2: ="Q"&ROUNDUP(MONTH(IFERROR(DATEVALUE(B2), DATE(RIGHT(B2,4), MID(B2,4,2), LEFT(B2,2))))/3,0) -> Q2
A3: TXN-1001 | B3: 45553 | C3: MapleTech Solutions | D3: East | E3: Kolkata | F3: Sneha Iyer | G3: Training Session | H3: One-time | I3: 1 | J3: 4999 | K3: 15 | L3: Yes | M3: INR | N3: Quarterly | O3: Credit Card | P3: Active | R3: =IF(P3="Active", I3*J3*(1-K3/100), 0) -> 4249.15 | S3: =IF(L3="Yes", R3-(R3/1.18), R3*0.18) -> 648.17542 | T3: =IF(L3="Yes", R3, R3+S3) -> 4249.15 | U3: ="Q"&ROUNDUP(MONTH(IFERROR(DATEVALUE(B3), DATE(RIGHT(B3,4), MID(B3,4,2), LEFT(B3,2))))/3,0) -> Q3
A4: TXN-1002 | B4: 45572 | C4: RedOak Enterprises | D4: North | E4: Jaipur | F4: Rohan Kapoor | G4: Training Session | H4: One-time | I4: 1 | J4: 4999 | K4: 10 | L4: No | M4: INR | N4: Monthly | O4: UPI | P4: Paused | R4: =IF(P4="Active", I4*J4*(1-K4/100), 0) -> 0 | S4: =IF(L4="Yes", R4-(R4/1.18), R4*0.18) -> 0 | T4: =IF(L4="Yes", R4, R4+S4) -> 0 | U4: ="Q"&ROUNDUP(MONTH(IFERROR(DATEVALUE(B4), DATE(RIGHT(B4,4), MID(B4,4,2), LEFT(B4,2))))/3,0) -> Q4
A5: TXN-1003 | B5: 45510 | C5: Pinnacle Infra | D5: East | E5: Patna | F5: Arjun Das | G5: Enterprise Plan | H5: Subscription | I5: 1 | J5: 9999 | K5: 5 | L5: No | M5: INR | N5: Quarterly | O5: UPI | P5: Active | Q5: 45540 | R5: =IF(P5="Active", I5*J5*(1-K5/100), 0) -> 9499.05 | S5: =IF(L5="Yes", R5-(R5/1.18), R5*0.18) -> 1709.829 | T5: =IF(L5="Yes", R5, R5+S5) -> 11208.879 | U5: ="Q"&ROUNDUP(MONTH(IFERROR(DATEVALUE(B5), DATE(RIGHT(B5,4), MID(B5,4,2), LEFT(B5,2))))/3,0) -> Q3
A6: TXN-1004 | B6: 45764 | C6: VeloCity Networks | D6: North | E6: Jaipur | F6: ARJUN DAS | G6: API Add-on | H6: Add-on | I6: 1 | J6: 1499 | K6: 20 | L6: Yes | M6: INR | N6: Annual | O6: UPI | P6: Active | R6: =IF(P6="Active", I6*J6*(1-K6/100), 0) -> 1199.2 | S6: =IF(L6="Yes", R6-(R6/1.18), R6*0.18) -> 182.92881 | T6: =IF(L6="Yes", R6, R6+S6) -> 1199.2 | U6: ="Q"&ROUNDUP(MONTH(IFERROR(DATEVALUE(B6), DATE(RIGHT(B6,4), MID(B6,4,2), LEFT(B6,2))))/3,0) -> Q2
A7: TXN-1005 | B7: 45498 | C7: ThunderBolt Inc | D7: West | E7: Ahmedabad | F7: Sneha Iyer | G7: Enterprise Plan | H7: Subscription | I7: 1 | J7: 9999 | K7: 0 | L7: No | M7: INR | N7: Quarterly | O7: Cheque | P7: Refunded | R7: =IF(P7="Active", I7*J7*(1-K7/100), 0) -> 0 | S7: =IF(L7="Yes", R7-(R7/1.18), R7*0.18) -> 0 | T7: =IF(L7="Yes", R7, R7+S7) -> 0 | U7: ="Q"&ROUNDUP(MONTH(IFERROR(DATEVALUE(B7), DATE(RIGHT(B7,4), MID(B7,4,2), LEFT(B7,2))))/3,0) -> Q3
A8: TXN-1006 | B8: 45610 | C8: NorthStar Digital | D8: East | E8: Kolkata | F8: Vikram Mehta | G8: Onboarding Fee | H8: One-time | I8: 1 | J8: 14999 | K8: 15 | L8: Yes | M8: INR | N8: Monthly | O8: Bank Transfer | P8: Active | R8: =IF(P8="Active", I8*J8*(1-K8/100), 0) -> 12749.15 | S8: =IF(L8="Yes", R8-(R8/1.18), R8*0.18) -> 1944.7856 | T8: =IF(L8="Yes", R8, R8+S8) -> 12749.15 | U8: ="Q"&ROUNDUP(MONTH(IFERROR(DATEVALUE(B8), DATE(RIGHT(B8,4), MID(B8,4,2), LEFT(B8,2))))/3,0) -> Q4
A9: TXN-1007 | B9: 45556 | C9: EverGreen IT | D9: North | E9: Jaipur | F9: Rohan Kapoor | G9: Training Session | H9: One-time | I9: 3 | J9: 4999 | K9: 0.15 | L9: Yes | M9: INR | N9: MONTHLY | O9: UPI | P9: Active | R9: =IF(P9="Active", I9*J9*(1-K9/100), 0) -> 14974.504 | S9: =IF(L9="Yes", R9-(R9/1.18), R9*0.18) -> 2284.2464 | T9: =IF(L9="Yes", R9, R9+S9) -> 14974.504 | U9: ="Q"&ROUNDUP(MONTH(IFERROR(DATEVALUE(B9), DATE(RIGHT(B9,4), MID(B9,4,2), LEFT(B9,2))))/3,0) -> Q3
A10: TXN-1008 | B10: 45509 | C10: QuantumBit Labs | D10: North | E10: Chandigarh | F10: VIKRAM MEHTA | G10: Storage Upgrade | H10: Add-on | I10: 3 | J10: 799 | K10: 0 | L10: No | M10: INR | N10: annual | O10: Cheque | P10: Cancelled | R10: =IF(P10="Active", I10*J10*(1-K10/100), 0) -> 0 | S10: =IF(L10="Yes", R10-(R10/1.18), R10*0.18) -> 0 | T10: =IF(L10="Yes", R10, R10+S10) -> 0 | U10: ="Q"&ROUNDUP(MONTH(IFERROR(DATEVALUE(B10), DATE(RIGHT(B10,4), MID(B10,4,2), LEFT(B10,2))))/3,0) -> Q3
A11: TXN-1009 | B11: 45535 | C11: AlphaTrack Systems | D11: South | E11: Hyderabad | F11: Arjun Das | G11: API Add-on | H11: Add-on | I11: 1 | J11: 1499 | K11: 0.15 | L11: Yes | M11: INR | N11: Annual | O11: Credit Card | P11: Active | R11: =IF(P11="Active", I11*J11*(1-K11/100), 0) -> 1496.7515 | S11: =IF(L11="Yes", R11-(R11/1.18), R11*0.18) -> 228.31803 | T11: =IF(L11="Yes", R11, R11+S11) -> 1496.7515 | U11: ="Q"&ROUNDUP(MONTH(IFERROR(DATEVALUE(B11), DATE(RIGHT(B11,4), MID(B11,4,2), LEFT(B11,2))))/3,0) -> Q3
A12: TXN-1010 | B12: 45816 | C12: VeloCity Networks | D12: North | E12: Delhi | F12: ARJUN DAS | G12: Training Session | H12: One-time | I12: 3 | J12: 4999 | K12: 0.15 | L12: No | M12: INR | N12: Monthly | O12: Credit Card | P12: Active | R12: =IF(P12="Active", I12*J12*(1-K12/100), 0) -> 14974.504 | S12: =IF(L12="Yes", R12-(R12/1.18), R12*0.18) -> 2695.4108 | T12: =IF(L12="Yes", R12, R12+S12) -> 17669.915 | U12: ="Q"&ROUNDUP(MONTH(IFERROR(DATEVALUE(B12), DATE(RIGHT(B12,4), MID(B12,4,2), LEFT(B12,2))))/3,0) -> Q2
A13: TXN-1011 | B13: 45808 | C13: ThunderBolt Inc | D13: East | E13: Guwahati | F13: Pooja Nair | G13: API Add-on | H13: Add-on | I13: 1 | J13: 1499 | K13: 10 | L13: Yes | M13: INR | N13: Monthly | O13: Bank Transfer | P13: Churned | R13: =IF(P13="Active", I13*J13*(1-K13/100), 0) -> 0 | S13: =IF(L13="Yes", R13-(R13/1.18), R13*0.18) -> 0 | T13: =IF(L13="Yes", R13, R13+S13) -> 0 | U13: ="Q"&ROUNDUP(MONTH(IFERROR(DATEVALUE(B13), DATE(RIGHT(B13,4), MID(B13,4,2), LEFT(B13,2))))/3,0) -> Q2
A14: TXN-1012 | B14: 45755 | C14: ThunderBolt Inc | D14: South | E14: Hyderabad | F14: Sneha Iyer | G14: API Add-on | H14: Add-on | I14: 5 | J14: 1499 | K14: 0 | L14: No | M14: INR | N14: monthly | O14: Cheque | P14: Paused | R14: =IF(P14="Active", I14*J14*(1-K14/100), 0) -> 0 | S14: =IF(L14="Yes", R14-(R14/1.18), R14*0.18) -> 0 | T14: =IF(L14="Yes", R14, R14+S14) -> 0 | U14: ="Q"&ROUNDUP(MONTH(IFERROR(DATEVALUE(B14), DATE(RIGHT(B14,4), MID(B14,4,2), LEFT(B14,2))))/3,0) -> Q2
A15: TXN-1013 | B15: 45706 | C15: CloudNine Systems | D15: South | E15: Kochi | F15: Pooja Nair | G15: Pro Plan | H15: Subscription | I15: 1 | J15: 2999 | K15: 0.1 | L15: Yes | M15: INR | N15: quarterly | O15: Credit Card | P15: Cancelled | R15: =IF(P15="Active", I15*J15*(1-K15/100), 0) -> 0 | S15: =IF(L15="Yes", R15-(R15/1.18), R15*0.18) -> 0 | T15: =IF(L15="Yes", R15, R15+S15) -> 0 | U15: ="Q"&ROUNDUP(MONTH(IFERROR(DATEVALUE(B15), DATE(RIGHT(B15,4), MID(B15,4,2), LEFT(B15,2))))/3,0) -> Q1
A16: TXN-1014 | B16: 45745 | C16: SunRise Technologies | D16: North | E16: Jaipur | F16: Vikram Mehta | G16: Pro Plan | H16: Subscription | I16: 1 | J16: 2999 | K16: 0 | L16: Yes | M16: INR | N16: Monthly | O16: Bank Transfer | P16: Churned | R16: =IF(P16="Active", I16*J16*(1-K16/100), 0) -> 0 | S16: =IF(L16="Yes", R16-(R16/1.18), R16*0.18) -> 0 | T16: =IF(L16="Yes", R16, R16+S16) -> 0 | U16: ="Q"&ROUNDUP(MONTH(IFERROR(DATEVALUE(B16), DATE(RIGHT(B16,4), MID(B16,4,2), LEFT(B16,2))))/3,0) -> Q1
A17: TXN-1015 | B17: 45607 | C17: UrbanGrid Analytics | D17: North | E17: Lucknow | F17: Rohan Kapoor | G17: Onboarding Fee | H17: One-time | I17: 5 | J17: 14999 | K17: 10 | L17: No | M17: INR | N17: Annual | O17: Credit Card | P17: Active | R17: =IF(P17="Active", I17*J17*(1-K17/100), 0) -> 67495.5 | S17: =IF(L17="Yes", R17-(R17/1.18), R17*0.18) -> 12149.19 | T17: =IF(L17="Yes", R17, R17+S17) -> 79644.69 | U17: ="Q"&ROUNDUP(MONTH(IFERROR(DATEVALUE(B17), DATE(RIGHT(B17,4), MID(B17,4,2), LEFT(B17,2))))/3,0) -> Q4
A18: TXN-1016 | B18: 45652 | C18: TechSpark Solutions | D18: West | E18: Mumbai | F18: rohan kapoor | G18: Pro Plan | H18: Subscription | I18: 1 | J18: 2999 | K18: 10 | L18: Yes | M18: INR | N18: Quarterly | O18: Credit Card | P18: Active | Q18: 46017 | R18: =IF(P18="Active", I18*J18*(1-K18/100), 0) -> 2699.1 | S18: =IF(L18="Yes", R18-(R18/1.18), R18*0.18) -> 411.72712 | T18: =IF(L18="Yes", R18, R18+S18) -> 2699.1 | U18: ="Q"&ROUNDUP(MONTH(IFERROR(DATEVALUE(B18), DATE(RIGHT(B18,4), MID(B18,4,2), LEFT(B18,2))))/3,0) -> Q4
A19: TXN-1017 | B19: 45553 | C19: IronClad Security | D19: North | E19: Chandigarh | F19: Vikram Mehta | G19: Starter Plan | H19: Subscription | I19: 1 | J19: 999 | K19: 10 | L19: No | M19: INR | N19: Annual | O19: Credit Card | P19: Active | Q19: 45583 | R19: =IF(P19="Active", I19*J19*(1-K19/100), 0) -> 899.1 | S19: =IF(L19="Yes", R19-(R19/1.18), R19*0.18) -> 161.838 | T19: =IF(L19="Yes", R19, R19+S19) -> 1060.938 | U19: ="Q"&ROUNDUP(MONTH(IFERROR(DATEVALUE(B19), DATE(RIGHT(B19,4), MID(B19,4,2), LEFT(B19,2))))/3,0) -> Q3
A20: TXN-1018 | B20: 45608 | C20: ThunderBolt Inc | D20: East | E20: Kolkata | F20: Arjun Das | G20: Pro Plan | H20: Subscription | I20: 1 | J20: 2999 | K20: 15 | L20: Yes | M20: INR | N20: MONTHLY | O20: UPI | P20: Active | Q20: 45973 | R20: =IF(P20="Active", I20*J20*(1-K20/100), 0) -> 2549.15 | S20: =IF(L20="Yes", R20-(R20/1.18), R20*0.18) -> 388.85339 | T20: =IF(L20="Yes", R20, R20+S20) -> 2549.15 | U20: ="Q"&ROUNDUP(MONTH(IFERROR(DATEVALUE(B20), DATE(RIGHT(B20,4), MID(B20,4,2), LEFT(B20,2))))/3,0) -> Q4
A21: TXN-1019 | B21: 45494 | C21: BrightEdge Digital | D21: West | E21: Pune | F21: Arjun Das | G21: Pro Plan | H21: Subscription | I21: 1 | J21: 2999 | K21: 5 | L21: No | M21: INR | N21: Quarterly | O21: Bank Transfer | P21: Cancelled | R21: =IF(P21="Active", I21*J21*(1-K21/100), 0) -> 0 | S21: =IF(L21="Yes", R21-(R21/1.18), R21*0.18) -> 0 | T21: =IF(L21="Yes", R21, R21+S21) -> 0 | U21: ="Q"&ROUNDUP(MONTH(IFERROR(DATEVALUE(B21), DATE(RIGHT(B21,4), MID(B21,4,2), LEFT(B21,2))))/3,0) -> Q3
A22: TXN-1020 | B22: 45684 | C22: QuantumBit Labs | D22: South | E22: Chennai | F22: vikram mehta | G22: API Add-on | H22: Add-on | I22: 5 | J22: 1499 | K22: 10 | L22: Yes | M22: INR | N22: ANNUAL | O22: Bank Transfer | P22: Active | R22: =IF(P22="Active", I22*J22*(1-K22/100), 0) -> 6745.5 | S22: =IF(L22="Yes", R22-(R22/1.18), R22*0.18) -> 1028.9746 | T22: =IF(L22="Yes", R22, R22+S22) -> 6745.5 | U22: ="Q"&ROUNDUP(MONTH(IFERROR(DATEVALUE(B22), DATE(RIGHT(B22,4), MID(B22,4,2), LEFT(B22,2))))/3,0) -> Q1
A23: TXN-1021 | B23: 45678 | C23: MetroSync Corp | D23: West | E23: Ahmedabad | F23: sneha iyer | G23: Starter Plan | H23: Subscription | I23: 1 | J23: 999 | K23: 10 | L23: No | M23: INR | N23: Annual | O23: Credit Card | P23: Active | Q23: 45708 | R23: =IF(P23="Active", I23*J23*(1-K23/100), 0) -> 899.1 | S23: =IF(L23="Yes", R23-(R23/1.18), R23*0.18) -> 161.838 | T23: =IF(L23="Yes", R23, R23+S23) -> 1060.938 | U23: ="Q"&ROUNDUP(MONTH(IFERROR(DATEVALUE(B23), DATE(RIGHT(B23,4), MID(B23,4,2), LEFT(B23,2))))/3,0) -> Q1
A24: TXN-1022 | B24: 45634 | C24: TerraFirm Solutions | D24: South | E24: Hyderabad | F24: Vikram Mehta | G24: Pro Plan | H24: Subscription | I24: 1 | J24: 2999 | K24: 0 | L24: Yes | M24: INR | N24: annual | O24: Credit Card | P24: Active | Q24: 45999 | R24: =IF(P24="Active", I24*J24*(1-K24/100), 0) -> 2999 | S24: =IF(L24="Yes", R24-(R24/1.18), R24*0.18) -> 457.47458 | T24: =IF(L24="Yes", R24, R24+S24) -> 2999 | U24: ="Q"&ROUNDUP(MONTH(IFERROR(DATEVALUE(B24), DATE(RIGHT(B24,4), MID(B24,4,2), LEFT(B24,2))))/3,0) -> Q4
A25: TXN-1023 | B25: 45793 | C25: SunRise Technologies | D25: South | E25: Hyderabad | F25: Vikram Mehta | G25: API Add-on | H25: Add-on | I25: 1 | J25: 1499 | K25: 10 | L25: No | M25: INR | N25: Annual | O25: Bank Transfer | P25: Active | R25: =IF(P25="Active", I25*J25*(1-K25/100), 0) -> 1349.1 | S25: =IF(L25="Yes", R25-(R25/1.18), R25*0.18) -> 242.838 | T25: =IF(L25="Yes", R25, R25+S25) -> 1591.938 | U25: ="Q"&ROUNDUP(MONTH(IFERROR(DATEVALUE(B25), DATE(RIGHT(B25,4), MID(B25,4,2), LEFT(B25,2))))/3,0) -> Q2
A26: TXN-1024 | B26: 45754 | C26: MetroSync Corp | D26: West | E26: Surat | F26: Sneha Iyer | G26: Onboarding Fee | H26: One-time | I26: 1 | J26: 14999 | K26: 15 | L26: No | M26: INR | N26: Annual | O26: Bank Transfer | P26: Refunded | R26: =IF(P26="Active", I26*J26*(1-K26/100), 0) -> 0 | S26: =IF(L26="Yes", R26-(R26/1.18), R26*0.18) -> 0 | T26: =IF(L26="Yes", R26, R26+S26) -> 0 | U26: ="Q"&ROUNDUP(MONTH(IFERROR(DATEVALUE(B26), DATE(RIGHT(B26,4), MID(B26,4,2), LEFT(B26,2))))/3,0) -> Q2
A27: TXN-1025 | B27: 45791 | C27: EverGreen IT | D27: West | E27: Pune | F27: Vikram Mehta | G27: Onboarding Fee | H27: One-time | I27: 1 | J27: 14999 | K27: 5 | L27: Yes | M27: INR | N27: MONTHLY | O27: Credit Card | P27: Churned | R27: =IF(P27="Active", I27*J27*(1-K27/100), 0) -> 0 | S27: =IF(L27="Yes", R27-(R27/1.18), R27*0.18) -> 0 | T27: =IF(L27="Yes", R27, R27+S27) -> 0 | U27: ="Q"&ROUNDUP(MONTH(IFERROR(DATEVALUE(B27), DATE(RIGHT(B27,4), MID(B27,4,2), LEFT(B27,2))))/3,0) -> Q2
A28: TXN-1026 | B28: 45809 | C28: CoralReef Data | D28: West | E28: Pune | F28: Pooja Nair | G28: Onboarding Fee | H28: One-time | I28: 1 | J28: 14999 | K28: 5 | L28: Yes | M28: INR | N28: Annual | O28: Credit Card | P28: Active | R28: =IF(P28="Active", I28*J28*(1-K28/100), 0) -> 14249.05 | S28: =IF(L28="Yes", R28-(R28/1.18), R28*0.18) -> 2173.5839 | T28: =IF(L28="Yes", R28, R28+S28) -> 14249.05 | U28: ="Q"&ROUNDUP(MONTH(IFERROR(DATEVALUE(B28), DATE(RIGHT(B28,4), MID(B28,4,2), LEFT(B28,2))))/3,0) -> Q2
A29: TXN-1027 | B29: 45700 | C29: CoralReef Data | D29: South | E29: Kochi | F29: Rohan Kapoor | G29: Onboarding Fee | H29: One-time | I29: 5 | J29: 14999 | K29: 15 | L29: Yes | M29: INR | N29: Annual | O29: Cheque | P29: Churned | R29: =IF(P29="Active", I29*J29*(1-K29/100), 0) -> 0 | S29: =IF(L29="Yes", R29-(R29/1.18), R29*0.18) -> 0 | T29: =IF(L29="Yes", R29, R29+S29) -> 0 | U29: ="Q"&ROUNDUP(MONTH(IFERROR(DATEVALUE(B29), DATE(RIGHT(B29,4), MID(B29,4,2), LEFT(B29,2))))/3,0) -> Q1
A30: TXN-1028 | B30: 45794 | C30: MapleTech Solutions | D30: East | E30: Bhubaneswar | F30: Arjun Das | G30: Training Session | H30: One-time | I30: 2 | J30: 4999 | K30: 10 | L30: No | M30: INR | N30: Quarterly | O30: Bank Transfer | P30: Active | R30: =IF(P30="Active", I30*J30*(1-K30/100), 0) -> 8998.2 | S30: =IF(L30="Yes", R30-(R30/1.18), R30*0.18) -> 1619.676 | T30: =IF(L30="Yes", R30, R30+S30) -> 10617.876 | U30: ="Q"&ROUNDUP(MONTH(IFERROR(DATEVALUE(B30), DATE(RIGHT(B30,4), MID(B30,4,2), LEFT(B30,2))))/3,0) -> Q2
A31: TXN-1029 | B31: 45751 | C31: VeloCity Networks | D31: West | E31: Pune | F31: SNEHA IYER | G31: Onboarding Fee | H31: One-time | I31: 1 | J31: 14999 | K31: 15 | L31: Yes | M31: INR | N31: Annual | O31: Cheque | P31: Active | R31: =IF(P31="Active", I31*J31*(1-K31/100), 0) -> 12749.15 | S31: =IF(L31="Yes", R31-(R31/1.18), R31*0.18) -> 1944.7856 | T31: =IF(L31="Yes", R31, R31+S31) -> 12749.15 | U31: ="Q"&ROUNDUP(MONTH(IFERROR(DATEVALUE(B31), DATE(RIGHT(B31,4), MID(B31,4,2), LEFT(B31,2))))/3,0) -> Q2
A32: TXN-1030 | B32: 45688 | C32: TEST_ACCOUNT | D32: North | E32: Jaipur | F32: Pooja Nair | G32: Starter Plan | H32: Subscription | I32: 1 | J32: 999 | K32: 0.15 | L32: No | M32: INR | N32: Quarterly | O32: Cheque | P32: Churned | R32: =IF(P32="Active", I32*J32*(1-K32/100), 0) -> 0 | S32: =IF(L32="Yes", R32-(R32/1.18), R32*0.18) -> 0 | T32: =IF(L32="Yes", R32, R32+S32) -> 0 | U32: ="Q"&ROUNDUP(MONTH(IFERROR(DATEVALUE(B32), DATE(RIGHT(B32,4), MID(B32,4,2), LEFT(B32,2))))/3,0) -> Q1
A33: TXN-1031 | B33: 31-03-2025 | C33: ZenithBridge Consulting | D33: West | E33: Pune | F33: Pooja Nair | G33: Training Session | H33: One-time | I33: 2 | J33: 4999 | K33: 0 | L33: No | M33: INR | N33: quarterly | O33: UPI | P33: Active | R33: =IF(P33="Active", I33*J33*(1-K33/100), 0) -> 9998 | S33: =IF(L33="Yes", R33-(R33/1.18), R33*0.18) -> 1799.64 | T33: =IF(L33="Yes", R33, R33+S33) -> 11797.64 | U33: ="Q"&ROUNDUP(MONTH(IFERROR(DATEVALUE(B33), DATE(RIGHT(B33,4), MID(B33,4,2), LEFT(B33,2))))/3,0) -> Q1
A34: TXN-1032 | B34: 45616 | C34: RedOak Enterprises | D34: East | E34: Bhubaneswar | F34: Arjun Das | G34: API Add-on | H34: Add-on | I34: 2 | J34: 1499 | K34: 0 | L34: Yes | M34: INR | N34: Annual | O34: Credit Card | P34: Active | R34: =IF(P34="Active", I34*J34*(1-K34/100), 0) -> 2998 | S34: =IF(L34="Yes", R34-(R34/1.18), R34*0.18) -> 457.32203 | T34: =IF(L34="Yes", R34, R34+S34) -> 2998 | U34: ="Q"&ROUNDUP(MONTH(IFERROR(DATEVALUE(B34), DATE(RIGHT(B34,4), MID(B34,4,2), LEFT(B34,2))))/3,0) -> Q4
A35: TXN-1033 | B35: 45716 | C35: UrbanGrid Analytics | D35: North | E35: Chandigarh | F35: Vikram Mehta | G35: Enterprise Plan | H35: Subscription | I35: 1 | J35: 9999 | K35: 5 | L35: Yes | M35: INR | N35: Quarterly | O35: Credit Card | P35: Active | Q35: 45746 | R35: =IF(P35="Active", I35*J35*(1-K35/100), 0) -> 9499.05 | S35: =IF(L35="Yes", R35-(R35/1.18), R35*0.18) -> 1449.0076 | T35: =IF(L35="Yes", R35, R35+S35) -> 9499.05 | U35: ="Q"&ROUNDUP(MONTH(IFERROR(DATEVALUE(B35), DATE(RIGHT(B35,4), MID(B35,4,2), LEFT(B35,2))))/3,0) -> Q1
A36: TXN-1034 | B36: 45677 | C36: IronClad Security | D36: North | E36: Delhi | F36: Rohan Kapoor | G36: Starter Plan | H36: Subscription | I36: 1 | J36: 999 | K36: 0.15 | L36: Yes | M36: INR | N36: Annual | O36: Credit Card | P36: Cancelled | R36: =IF(P36="Active", I36*J36*(1-K36/100), 0) -> 0 | S36: =IF(L36="Yes", R36-(R36/1.18), R36*0.18) -> 0 | T36: =IF(L36="Yes", R36, R36+S36) -> 0 | U36: ="Q"&ROUNDUP(MONTH(IFERROR(DATEVALUE(B36), DATE(RIGHT(B36,4), MID(B36,4,2), LEFT(B36,2))))/3,0) -> Q1
A37: TXN-1035 | B37: 45480 | C37: UrbanGrid Analytics | D37: East | E37: Guwahati | F37: ARJUN DAS | G37: Onboarding Fee | H37: One-time | I37: 2 | J37: 14999 | K37: 10 | L37: No | M37: INR | N37: Quarterly | O37: UPI | P37: Cancelled | R37: =IF(P37="Active", I37*J37*(1-K37/100), 0) -> 0 | S37: =IF(L37="Yes", R37-(R37/1.18), R37*0.18) -> 0 | T37: =IF(L37="Yes", R37, R37+S37) -> 0 | U37: ="Q"&ROUNDUP(MONTH(IFERROR(DATEVALUE(B37), DATE(RIGHT(B37,4), MID(B37,4,2), LEFT(B37,2))))/3,0) -> Q3
A38: TXN-1036 | B38: 45518 | C38: SunRise Technologies | D38: West | E38: Surat | F38: Rohan Kapoor | G38: API Add-on | H38: Add-on | I38: 2 | J38: 1499 | K38: 20 | L38: Yes | M38: INR | N38: Annual | O38: UPI | P38: Active | R38: =IF(P38="Active", I38*J38*(1-K38/100), 0) -> 2398.4 | S38: =IF(L38="Yes", R38-(R38/1.18), R38*0.18) -> 365.85763 | T38: =IF(L38="Yes", R38, R38+S38) -> 2398.4 | U38: ="Q"&ROUNDUP(MONTH(IFERROR(DATEVALUE(B38), DATE(RIGHT(B38,4), MID(B38,4,2), LEFT(B38,2))))/3,0) -> Q3
A39: TXN-1037 | B39: 45833 | C39: FusionWave Media | D39: West | E39: Pune | F39: Arjun Das | G39: Starter Plan | H39: Subscription | I39: 1 | J39: 999 | K39: 0.1 | L39: No | M39: INR | N39: Monthly | O39: Bank Transfer | P39: Paused | R39: =IF(P39="Active", I39*J39*(1-K39/100), 0) -> 0 | S39: =IF(L39="Yes", R39-(R39/1.18), R39*0.18) -> 0 | T39: =IF(L39="Yes", R39, R39+S39) -> 0 | U39: ="Q"&ROUNDUP(MONTH(IFERROR(DATEVALUE(B39), DATE(RIGHT(B39,4), MID(B39,4,2), LEFT(B39,2))))/3,0) -> Q2
A40: TXN-1038 | B40: 45828 | C40: TEST_ACCOUNT | D40: West | E40: Surat | F40: VIKRAM MEHTA | G40: Training Session | H40: One-time | I40: 5 | J40: 4999 | K40: 20 | L40: No | M40: INR | N40: Quarterly | O40: Cheque | P40: Active | R40: =IF(P40="Active", I40*J40*(1-K40/100), 0) -> 19996 | S40: =IF(L40="Yes", R40-(R40/1.18), R40*0.18) -> 3599.28 | T40: =IF(L40="Yes", R40, R40+S40) -> 23595.28 | U40: ="Q"&ROUNDUP(MONTH(IFERROR(DATEVALUE(B40), DATE(RIGHT(B40,4), MID(B40,4,2), LEFT(B40,2))))/3,0) -> Q2
...

Sheet Questions
A1: Questions | B1: Answers
A2: List 3 issues (anomalies) you found in the dataset and explain how it affects the analysis | B2: 1. Date/Month Inconsistency: The dataset used mixed date formats (e.g., YYYY-MM-DD and DD-MM-YYYY), which caused standard date-extraction formulas to fail. I implemented a robust DATEVALUE and TRIM fallback formula to ensure accurate Quarter (Q1–Q4) and MoM mapping. 2. Tax Calculation Mismatches: Manual entries for "Tax Amount" and "Final Amount" were inconsistent with the 18% GST rule for "Tax Included" vs. "Excluded" rows. I standardized these using conditional logic to prevent revenue reporting errors. 3. String Normalization (Casing/Spaces): Inconsistent capitalization (e.g., "Arjun Das" vs "ARJUN DAS") and trailing spaces in the "Status" column threatened to skew unique customer counts. I utilized UPPER(TRIM()) logic to ensure data integrity for all pivot and lookup operations.
A3: Fill the following columns in the Transactions sheet using formulas. Leave the formula intact — do NOT paste as values. 1. "Net Amount" (Column R) = Quantity × Unit Price (INR) × (1 − Discount%) - Apply ONLY for rows where Status = "Active" - For all other statuses, Net Amount = 0 2. "Tax Amount (18% GST)" (Column S): - If Tax Included = "Yes": Tax Amount = Net Amount − (Net Amount / 1.18) - If Tax Included = "No": Tax Amount = Net Amount × 0.18 3. "Final Amount" (Column T): - If Tax Included = "Yes": Final Amount = Net Amount - If Tax Included = "No": Final Amount = Net Amount + Tax Amount 4. "Quarter" (Column U) = Extract the calendar quarter from Transaction Date (Q1, Q2, Q3, Q4) Write "Done" in cell B2 once formulas are in place. | B3: 1. =IF(P2="Active", I2*J2*(1-(K2/100)), 0) 2. =IF(L2="Yes", R2-(R2/1.18), R2*0.18) 3. =IF(L2="Yes", R2, R2+S2) 4. ="Q"&ROUNDUP(MONTH(IFERROR(DATEVALUE(B2), DATE(RIGHT(B2,4), MID(B2,4,2), LEFT(B2,2))))/3,0)
A4: Create a new subsheet named "Region Summary" with a pivot table showing: - Rows: Region - Values: Total Final Amount, Count of Active Transactions, Average Discount % (Include ONLY Active status & INR currency transactions) In cell B3, write which Region has the highest Average Final Amount per Active transaction. | B4: =IFERROR(__xludf.DUMMYFUNCTION("INDEX(SORT(FILTER({'Region Summary'!A2:A1000,'Region Summary'!B2:B1000/'Region Summary'!C2:C1000},'Region Summary'!A2:A1000<>""""),2,FALSE),1,1)"),"North") -> North
A5: What is the total Final Amount from "Subscription" type products where: - Status = "Active" - Currency = "INR" - Discount % is a valid percentage (i.e., between 0 and 100, not a decimal like 0.10 or 0.15) Write the formula-based answer in cell B4. | B5: =SUMPRODUCT((Transactions!H2:H2000="Subscription")*(Transactions!P2:P2000="Active")*(Transactions!M2:M2000="INR")*(Transactions!K2:K2000>=0)*(Transactions!K2:K2000<=100)*(Transactions!T2:T2000)) -> 167924.75
A6: Create a new subsheet named "Monthly Trend" showing: - Column A: Month (extracted from Transaction Date, formatted as MMM-YYYY, e.g., Jul-2024) - Column B: Monthly Revenue (sum of Final Amount for that month, Active + INR only) - Column C: Cumulative Revenue (running total up to that month) - Column D: MoM Growth % = (Current Month − Previous Month) / Previous Month × 100. First month = "N/A". All values must be formula-driven. Write the month with the highest MoM growth % in cell B5. | B6: {=INDEX('Monthly Trend'!A2:A1000, MATCH(MAX('Monthly Trend'!D2:D1000), 'Monthly Trend'!D2:D1000, 0))} -> 2025-01
A7: How many unique customers have at least one "Active" transaction AND at least one "Cancelled" or "Churned" transaction? (A customer counts only if they appear in BOTH categories) Write the count (using formula) in cell B6. | B7: {=SUMPRODUCT((COUNTIFS(Transactions!$C$2:$C$200, UNIQUE(TRIM(Transactions!$C$2:$C$200)), Transactions!$P$2:$P$200, "Active")>0) * (COUNTIFS(Transactions!$C$2:$C$200, UNIQUE(TRIM(Transactions!$C$2:$C$200)), Transactions!$P$2:$P$200, "Cancelled") + COUNTIFS(Transactions!$C$2:$C$200, UNIQUE(TRIM(Transactions!$C$2:$C$200)), Transactions!$P$2:$P$200, "Churned")>0))} -> 27

Sheet Region Summary
E2: {=IF(B2:B1000="",, B2:B1000 / C2:C1000)} -> 6155.0077
E3: 15000.566
E4: 4207.412
E5: 7227.9782
E6: 8263.7299

Sheet Monthly Trend
A1: Month | B1: Monthly Revenue | C1: Cumulative Revenue | D1: MoM Growth %
A2: 2024-07 | B2: =SUMPRODUCT( (IFERROR(TEXT(Transactions!$B$2:$B$2000, "yyyy-mm"), RIGHT(Transactions!$B$2:$B$2000, 4)&"-"&MID(Transactions!$B$2:$B$2000, 4, 2)) = A2) * (Transactions!$P$2:$P$2000 = "Active") * (Transactions!$M$2:$M$2000 = "INR") * Transactions!$T$2:$T$2000 ) -> 64215.244 | C2: =B2 -> 64215.244 | D2: N/A
A3: 2024-08 | B3: =SUMPRODUCT( (IFERROR(TEXT(Transactions!$B$2:$B$2000, "yyyy-mm"), RIGHT(Transactions!$B$2:$B$2000, 4)&"-"&MID(Transactions!$B$2:$B$2000, 4, 2)) = A3) * (Transactions!$P$2:$P$2000 = "Active") * (Transactions!$M$2:$M$2000 = "INR") * Transactions!$T$2:$T$2000 ) -> 104148.37 | C3: =C2 + B3 -> 168363.62 | D3: =(B3-B2)/B2 -> 0.6218637
A4: 27-08-2024 | B4: =SUMPRODUCT( (IFERROR(TEXT(Transactions!$B$2:$B$2000, "yyyy-mm"), RIGHT(Transactions!$B$2:$B$2000, 4)&"-"&MID(Transactions!$B$2:$B$2000, 4, 2)) = A4) * (Transactions!$P$2:$P$2000 = "Active") * (Transactions!$M$2:$M$2000 = "INR") * Transactions!$T$2:$T$2000 ) -> 0 | C4: =C3 + B4 -> 168363.62 | D4: N/A
A5: 2024-09 | B5: =SUMPRODUCT( (IFERROR(TEXT(Transactions!$B$2:$B$2000, "yyyy-mm"), RIGHT(Transactions!$B$2:$B$2000, 4)&"-"&MID(Transactions!$B$2:$B$2000, 4, 2)) = A5) * (Transactions!$P$2:$P$2000 = "Active") * (Transactions!$M$2:$M$2000 = "INR") * Transactions!$T$2:$T$2000 ) -> 72642.698 | C5: =C4 + B5 -> 241006.32 | D5: =(B5-B3)/B3 -> -0.30250761
A6: 2024-10 | B6: =SUMPRODUCT( (IFERROR(TEXT(Transactions!$B$2:$B$2000, "yyyy-mm"), RIGHT(Transactions!$B$2:$B$2000, 4)&"-"&MID(Transactions!$B$2:$B$2000, 4, 2)) = A6) * (Transactions!$P$2:$P$2000 = "Active") * (Transactions!$M$2:$M$2000 = "INR") * Transactions!$T$2:$T$2000 ) -> 22074.427 | C6: =C5 + B6 -> 263080.74 | D6: =(B6-B5)/B5 -> -0.69612325
A7: 2024-11 | B7: =SUMPRODUCT( (IFERROR(TEXT(Transactions!$B$2:$B$2000, "yyyy-mm"), RIGHT(Transactions!$B$2:$B$2000, 4)&"-"&MID(Transactions!$B$2:$B$2000, 4, 2)) = A7) * (Transactions!$P$2:$P$2000 = "Active") * (Transactions!$M$2:$M$2000 = "INR") * Transactions!$T$2:$T$2000 ) -> 196104.06 | C7: =C6 + B7 -> 459184.8 | D7: =(B7-B6)/B6 -> 7.8837666
A8: 2024-12 | B8: =SUMPRODUCT( (IFERROR(TEXT(Transactions!$B$2:$B$2000, "yyyy-mm"), RIGHT(Transactions!$B$2:$B$2000, 4)&"-"&MID(Transactions!$B$2:$B$2000, 4, 2)) = A8) * (Transactions!$P$2:$P$2000 = "Active") * (Transactions!$M$2:$M$2000 = "INR") * Transactions!$T$2:$T$2000 ) -> 9593.2515 | C8: =C7 + B8 -> 468778.05 | D8: =(B8-B7)/B7 -> -0.95108081
A9: 2025-01 | B9: =SUMPRODUCT( (IFERROR(TEXT(Transactions!$B$2:$B$2000, "yyyy-mm"), RIGHT(Transactions!$B$2:$B$2000, 4)&"-"&MID(Transactions!$B$2:$B$2000, 4, 2)) = A9) * (Transactions!$P$2:$P$2000 = "Active") * (Transactions!$M$2:$M$2000 = "INR") * Transactions!$T$2:$T$2000 ) -> 87251.879 | C9: =C8 + B9 -> 556029.93 | D9: =(B9-B8)/B8 -> 8.0951309
A10: 2025-02 | B10: =SUMPRODUCT( (IFERROR(TEXT(Transactions!$B$2:$B$2000, "yyyy-mm"), RIGHT(Transactions!$B$2:$B$2000, 4)&"-"&MID(Transactions!$B$2:$B$2000, 4, 2)) = A10) * (Transactions!$P$2:$P$2000 = "Active") * (Transactions!$M$2:$M$2000 = "INR") * Transactions!$T$2:$T$2000 ) -> 11002.547 | C10: =C9 + B10 -> 567032.48 | D10: =(B10-B9)/B9 -> -0.87389902
A11: 20-02-2025 | B11: =SUMPRODUCT( (IFERROR(TEXT(Transactions!$B$2:$B$2000, "yyyy-mm"), RIGHT(Transactions!$B$2:$B$2000, 4)&"-"&MID(Transactions!$B$2:$B$2000, 4, 2)) = A11) * (Transactions!$P$2:$P$2000 = "Active") * (Transactions!$M$2:$M$2000 = "INR") * Transactions!$T$2:$T$2000 ) -> 0 | C11: =C10 + B11 -> 567032.48 | D11: N/A
A12: 2025-03 | B12: =SUMPRODUCT( (IFERROR(TEXT(Transactions!$B$2:$B$2000, "yyyy-mm"), RIGHT(Transactions!$B$2:$B$2000, 4)&"-"&MID(Transactions!$B$2:$B$2000, 4, 2)) = A12) * (Transactions!$P$2:$P$2000 = "Active") * (Transactions!$M$2:$M$2000 = "INR") * Transactions!$T$2:$T$2000 ) -> 79148.064 | C12: =C11 + B12 -> 646180.54 | D12: =(B12-B10)/B10 -> 6.1936129
A13: 31-03-2025 | B13: =SUMPRODUCT( (IFERROR(TEXT(Transactions!$B$2:$B$2000, "yyyy-mm"), RIGHT(Transactions!$B$2:$B$2000, 4)&"-"&MID(Transactions!$B$2:$B$2000, 4, 2)) = A13) * (Transactions!$P$2:$P$2000 = "Active") * (Transactions!$M$2:$M$2000 = "INR") * Transactions!$T$2:$T$2000 ) -> 11797.64 | C13: =C12 + B13 -> 657978.18 | D13: N/A
A14: 2025-04 | B14: =SUMPRODUCT( (IFERROR(TEXT(Transactions!$B$2:$B$2000, "yyyy-mm"), RIGHT(Transactions!$B$2:$B$2000, 4)&"-"&MID(Transactions!$B$2:$B$2000, 4, 2)) = A14) * (Transactions!$P$2:$P$2000 = "Active") * (Transactions!$M$2:$M$2000 = "INR") * Transactions!$T$2:$T$2000 ) -> 52654.162 | C14: =C13 + B14 -> 710632.34 | D14: =(B14-(B13+B12))/(B13+B12) -> -0.42103739
A15: 2025-05 | B15: =SUMPRODUCT( (IFERROR(TEXT(Transactions!$B$2:$B$2000, "yyyy-mm"), RIGHT(Transactions!$B$2:$B$2000, 4)&"-"&MID(Transactions!$B$2:$B$2000, 4, 2)) = A15) * (Transactions!$P$2:$P$2000 = "Active") * (Transactions!$M$2:$M$2000 = "INR") * Transactions!$T$2:$T$2000 ) -> 36873.134 | C15: =C14 + B15 -> 747505.48 | D15: =(B15-B14)/B14 -> -0.29971094
A16: 2025-06 | B16: =SUMPRODUCT( (IFERROR(TEXT(Transactions!$B$2:$B$2000, "yyyy-mm"), RIGHT(Transactions!$B$2:$B$2000, 4)&"-"&MID(Transactions!$B$2:$B$2000, 4, 2)) = A16) * (Transactions!$P$2:$P$2000 = "Active") * (Transactions!$M$2:$M$2000 = "INR") * Transactions!$T$2:$T$2000 ) -> 94659.603 | C16: =C15 + B16 -> 842165.08 | D16: =(B16-B15)/B15 -> 1.56717
A17: 2025-09 | B17: =SUMPRODUCT( (IFERROR(TEXT(Transactions!$B$2:$B$2000, "yyyy-mm"), RIGHT(Transactions!$B$2:$B$2000, 4)&"-"&MID(Transactions!$B$2:$B$2000, 4, 2)) = A17) * (Transactions!$P$2:$P$2000 = "Active") * (Transactions!$M$2:$M$2000 = "INR") * Transactions!$T$2:$T$2000 ) -> 8999.1 | C17: =C16 + B17 -> 851164.18 | D17: =(B17-B16)/B16 -> -0.90493199
